Workbook

Sheet Report
A1: LLM HOSTING COST ESTIMATE - EXECUTIVE SUMMARY
A2: ="Prepared from published US list prices, August 2026. Model: "&Simple_Calc!$B$6&" | Cloud: "&Calculator!$B$37 -> Prepared from published US list prices, August 2026. Model: Large - top-tier assistant, complex reasoning and long documents | Cloud: Microsoft Azure
A4: 1. WHAT WAS ASKED FOR
A5: Model | B5: =Simple_Calc!$B$6 -> Large - top-tier assistant, complex reasoning and long documents
A6: Size and quality setting | B6: =TEXT(Calculator!$D$6,"#,##0")&" billion parameters at "&Calculator!$D$7 -> 70 billion parameters at FP8 / INT8 - balanced
A7: Expected traffic | B7: =IF(Inference!$B$6=Rates!$I$46,"Not specified - sized on memory only",TEXT(Inference!$B$7,"#,##0")&" requests/month ("&TEXT(Inference!$B$8,"#,##0")&" in / "&TEXT(Inference!$B$9,"#,##0")&" out tokens each)") -> 500,000 requests/month (800 in / 400 out tokens each)
A8: Availability | B8: =TEXT(Calculator!$D$17,"#,##0")&" hours/day over "&TEXT(Calculator!$D$18,"#,##0.0")&" days/month = "&TEXT(Calculator!$B$45,"#,##0")&" billed hours" -> 24 hours/day over 30.4 days/month = 730 billed hours
A9: Region and pricing basis | B9: =Calculator!$B$14&" | "&Calculator!$D$16 -> US (baseline) | On-demand (pay as you go)
A11: 2. RECOMMENDATION
A12: Cloud | B12: =Calculator!$B$37 -> Microsoft Azure
A13: Machine type | B13: =Calculator!$B$36 -> Standard_NC40ads_H100_v5
A14: GPU | B14: =TEXT(Calculator!$B$39,"#,##0")&" x "&Calculator!$B$38&" ("&TEXT(Calculator!$B$40,"#,##0")&" GB GPU memory per machine)" -> 1 x NVIDIA H100 NVL (94 GB GPU memory per machine)
A15: Machines required | B15: =TEXT(Calculator!$D$9,"#,##0") -> 1 | C15: =IF(Inference!$B$23>1,"Set by throughput: the peak load needs this many to keep up","One machine covers the load") -> One machine covers the load
A16: GPU memory the model needs | B16: =TEXT(Calculator!$B$10,"#,##0")&" GB per copy" -> 91 GB per copy | C16: Weights plus headroom for the conversation cache
A17: Basis for the choice | B17: ="Cheapest option that both fits in memory and meets the peak token rate" -> Cheapest option that both fits in memory and meets the peak token rate
A19: 3. MONTHLY COST | C19: Share of total
A20: GPU compute | B20: =Calculator!$B$48 -> 5095.9584 | C20: =IFERROR(B20/$B$25,0) -> 0.41559768
A21: Disk storage | B21: =Calculator!$B$49 -> 40.5 | C21: =IFERROR(B21/$B$25,0) -> 0.003302952
A22: Data transfer out | B22: =Calculator!$B$50 -> 165.3 | C22: =IFERROR(B22/$B$25,0) -> 0.013480938
A23: Managed platform | B23: =Calculator!$B$51 -> 0 | C23: =IFERROR(B23/$B$25,0) -> 0
A24: Support and labour | B24: =Calculator!$B$52 -> 6960 | C24: =IFERROR(B24/$B$25,0) -> 0.56761843
A25: TOTAL PER MONTH | B25: =Calculator!$B$53 -> 12261.758
A26: TOTAL PER YEAR | B26: =Calculator!$B$54 -> 147141.1
A28: 4. GOOGLE CLOUD vs MICROSOFT AZURE
A29: Google Cloud, best option | B29: =Comparison!$B$5 -> g2-standard-96 | C29: =Comparison!$B$22 -> 13083.169
A30: Microsoft Azure, best option | B30: =Comparison!$C$5 -> Standard_NC40ads_H100_v5 | C30: =Comparison!$C$22 -> 12261.758
A31: Verdict | B31: =Comparison!$B$25 -> Microsoft Azure saves about $821 per month (6.3% less)
A33: 5. CAPACITY AND UNIT ECONOMICS
A34: Tokens per second, one machine | B34: =IF(Inference!$B$6=Rates!$I$46,"not sized",TEXT(Inference!$B$22,"#,##0")) -> 624 | C34: Bandwidth model, accurate to roughly a factor of two
A35: Peak tokens per second needed | B35: =IF(Inference!$B$6=Rates!$I$46,"not specified",TEXT(Inference!$B$16,"#,##0")) -> 274
A36: Spare capacity at peak | B36: =IF(Inference!$B$6=Rates!$I$46,"n/a",TEXT(Inference!$B$26,"0.0%")) -> 127.8%
A37: Speed one user would see | B37: =IF(Inference!$B$6=Rates!$I$46,"n/a",TEXT(Inference!$B$25,"#,##0")&" tokens/sec"&IF(Inference!$B$25<10," - slow"," - acceptable")) -> 39 tokens/sec - acceptable
A38: Cost per million output tokens | B38: =IF(Inference!$B$6=Rates!$I$46,"n/a - traffic not specified",TEXT(Inference!$B$31,"$#,##0.00")) -> $61.31 | C38: Compare directly against a pay-per-token API quote
A39: Cost per 1,000 requests | B39: =IF(Inference!$B$6=Rates!$I$46,"n/a",TEXT(Inference!$B$32,"$#,##0.00")) -> $24.52
A40: Pay-per-token alternative | B40: =IF(Inference!$B$7<=0,"not compared - traffic not specified",Calculator!$B$60&" at $"&TEXT(Calculator!$B$70,"#,##0")&"/month") -> Gemini 3.5 Flash-Lite at $2,940/month | C40: Same traffic, no machines to run. See the Comparison tab for the cheapest on each cloud
A41: Cheaper route on these numbers | B41: =IF(Inference!$B$7<=0,"n/a",IF(Calculator!$B$70<Calculator!$B$53,"Pay per token - saves $"&TEXT(Calculator!$B$53-Calculator!$B$70,"#,##0")&"/month","Self-host - saves $"&TEXT(Calculator!$B$70-Calculator!$B$53,"#,##0")&"/month")) -> Pay per token - saves $9,322/month
A42: Support level applied | B42: =Calculator!$B$128&" - "&TEXT(Calculator!$B$31,"#,##0")&" engineer hours/month at $"&TEXT(Calculator!$B$33,"#,##0")&"/hour" -> Medium - 60 engineer hours/month at $116/hour
A44: 6. WHAT COULD MOVE THIS NUMBER
A45: ="Price confidence for the chosen machine: "&IF(Calculator!$B$122=0,"n/a",INDEX(GPU_Price_List!$Q$5:$Q$35,Calculator!$B$121))&IF(Calculator!$B$122=0,"",IF(ISNUMBER(SEARCH("estimate",INDEX(GPU_Price_List!$Q$5:$Q$35,Calculator!$B$121)))," - CONFIRM THIS RATE BEFORE COMMITTING BUDGET","")) -> Price confidence for the chosen machine: Published list price
A46: ="Throughput assumes a batching gain of "&TEXT(Rates!$B$108,"#,##0")&"x from a modern serving stack. A naive setup would need several times more machines." -> Throughput assumes a batching gain of 16x from a modern serving stack. A naive setup would need several times more machines.
...

Sheet Simple_Calc
A1: Quick Estimate - three questions
A2: Answer the three questions below by clicking each yellow box and picking from the list. Your estimate appears underneath.
A3: No technical knowledge needed. Everything else is worked out for you on the Calculator tab.
A5: 1. How big is the AI model you want to run?
B6: Large - top-tier assistant, complex reasoning and long documents | C6: If you are not sure, pick Large - it is the most common choice for a serious assistant.
A8: 2. How much use will it get?
B9: A whole department, running around the clock | C9: This sets how many hours a month you pay for - usually the biggest lever on the bill.
A11: 3. What matters most to you?
B12: A balance of cost and reliability | C12: Lowest cost accepts machines that can be interrupted. Reliability commits to a year and adds a managed platform.
A14: WHAT THIS MEANS - these values are sent to the Calculator tab
A15: Setting on the Calculator tab | B15: Comes from | C15: Value sent
A16: Model size (billions of parameters) | B16: Question 1 | C16: =INDEX(Rates!$B$89:$B$92,MATCH($B$6,Rates!$A$89:$A$92,0)) -> 70
A17: Disk storage per copy (GB) | B17: Question 1 | C17: =INDEX(Rates!$C$89:$C$92,MATCH($B$6,Rates!$A$89:$A$92,0)) -> 500
A18: Hours running per day | B18: Question 2 | C18: =INDEX(Rates!$B$95:$B$98,MATCH($B$9,Rates!$A$95:$A$98,0)) -> 24
A19: Days running per month | B19: Question 2 | C19: =INDEX(Rates!$C$95:$C$98,MATCH($B$9,Rates!$A$95:$A$98,0)) -> 30.42
A20: Minimum copies of the model | B20: Question 2 | C20: =INDEX(Rates!$D$95:$D$98,MATCH($B$9,Rates!$A$95:$A$98,0)) -> 1
A21: Data sent out to users (GB per month) | B21: Question 2 | C21: =INDEX(Rates!$E$95:$E$98,MATCH($B$9,Rates!$A$95:$A$98,0)) -> 2000
A22: Precision / quantization | B22: Question 3 | C22: =INDEX(Rates!$B$101:$B$103,MATCH($B$12,Rates!$A$101:$A$103,0)) -> FP8 / INT8 - balanced
A23: Pricing model | B23: Question 3 | C23: =INDEX(Rates!$C$101:$C$103,MATCH($B$12,Rates!$A$101:$A$103,0)) -> On-demand (pay as you go)
A24: Managed AI platform | B24: Question 3 | C24: =INDEX(Rates!$D$101:$D$103,MATCH($B$12,Rates!$A$101:$A$103,0)) -> No - plain virtual machines
A26: Support level, cloud choice, region and disk type are not asked here. Support is recommended automatically from the model size, the cloud is set to compare both, and the rest keep sensible defaults. Change any of them on the Calculator tab.
A29: YOUR ESTIMATE
A30: GPU memory your model needs (GB) | B30: =Calculator!$B$10 -> 91
A31: Cheapest machine that fits | B31: =Calculator!$B$36 -> Standard_NC40ads_H100_v5
A32: On which cloud | B32: =Calculator!$B$37 -> Microsoft Azure
A33: Hours you pay for each month | B33: =Calculator!$B$45 -> 730.08
A34: Machines being paid for | B34: =Calculator!$D$9 -> 1 | C34: =IF(Calculator!$D$9>$C$20,"Raised from "&$C$20&" because the traffic on the Inference tab needs "&Inference!$B$23&" machines to keep up","Matches the minimum above") -> Matches the minimum above
A36: Machines and storage | B36: =Calculator!$B$48+Calculator!$B$49+Calculator!$B$50+Calculator!$B$51 -> 5301.7584
A37: People to support it | B37: =Calculator!$B$52 -> 6960
A38: TOTAL PER MONTH | B38: =Calculator!$B$53 -> 12261.758
A39: TOTAL PER YEAR | B39: =Calculator!$B$54 -> 147141.1
A41: In plain words | B41: =IF(Calculator!$B$122=0,"No single machine is big enough for a model this size at this quality setting. Try answering ""Lowest possible cost"" to question 3, or pick a smaller model in question 1.","Running a "&LOWER(LEFT($B$6,FIND(" ",$B$6)-1))&" model this way costs about $"&TEXT(Calculator!$B$53,"#,##0")&" a month, of which $"&TEXT(Calculator!$B$52,"#,##0")&" is the people who look after it and $"&TEXT(Calculator!$B$53-Calculator!$B$52,"#,##0")&" is the cloud bill. That is $"&TEXT(Calculator!$B$54,"#,##0")&" over a year.") -> Running a large model this way costs about $12,262 a month, of which $6,960 is the people who look after it and $5,302 is the cloud bill. That is $147,141 over a year.
A45: Before you use this number:
A46: - It is a planning estimate from published US list prices, not a quote.
A47: - Turning the machines off when nobody is using them is the single biggest saving available - that is question 2.
A48: - The Comparison tab shows Google Cloud and Azure side by side for the same answers.
A49: - If three questions are not enough, switch the Calculator tab to Expert mode and edit any value directly.
A51: OR DON'T RUN IT YOURSELF - pay per token instead
A52: Cheapest hosted model for this traffic | B52: =IFERROR(INDEX(Rates!$A$114:$A$134,MATCH(MIN(Rates!$I$114:$I$134),Rates!$I$114:$I$134,0)),"-") -> Gemini 2.5 Flash-Lite | C52: Chosen across both clouds on price alone. Pick a specific model on the Calculator tab, step 7.
A53: Runs on | B53: =IFERROR(INDEX(Rates!$B$114:$B$134,MATCH(MIN(Rates!$I$114:$I$134),Rates!$I$114:$I$134,0)),"-") -> Google Cloud
...

Sheet Calculator
A1: LLM Hosting Cost Calculator - Google Cloud vs Microsoft Azure
A2: Every yellow box on this tab is editable and takes effect immediately. Rows marked >> start out blank and borrow their value from the Simple_Calc tab until you type over them. Your estimate builds itself in step 6.
A3: Nothing here connects to a live account - it is a planning estimate using published US list prices from August 2026.
A4: Rows marked >> | B4: leave blank = use Simple_Calc | C4: Type anything into a yellow box and it takes over that row straight away. Clear the box to hand the row back to Simple_Calc. Every other row is yours as normal. | D4: Value in use | E4: Coming from
A5: STEP 1 - YOUR MODEL
A6: >> Model size (billions of parameters) | C6: e.g. 8 for an 8B model, 70 for a 70B model, 671 for DeepSeek-size | D6: =IF($B$6="",Simple_Calc!$C$16,$B$6) -> 70 | E6: =IF($B$6="","Simple_Calc","your entry") -> Simple_Calc
A7: >> Precision / quantization | C7: INT4 needs a quarter of the memory of FP16. | D7: =IF($B$7="",Simple_Calc!$C$22,$B$7) -> FP8 / INT8 - balanced | E7: =IF($B$7="","Simple_Calc","your entry") -> Simple_Calc
A8: Extra memory headroom (%) | B8: 0.3 | C8: Covers the conversation cache and working memory. 30% is a safe default.
A9: >> How many copies of the model to run | C9: Raised automatically if the Inference tab says the traffic needs more machines. | D9: =MAX(IF($B$9="",Simple_Calc!$C$20,$B$9),$B$130) -> 1 | E9: =IF($B$9="","Simple_Calc","your entry") -> Simple_Calc
A10: GPU memory needed for ONE copy (GB) | B10: =ROUNDUP($D$6*INDEX(Rates!$B$39:$B$41,MATCH($D$7,Rates!$A$39:$A$41,0))*(1+B8),0) -> 91 | C10: Calculated for you - this decides which machines are big enough.
A12: STEP 2 - WHERE TO RUN IT
A13: Cloud provider | B13: Compare both | C13: Choose one, or 'Compare both' to let the sheet pick the cheaper.
A14: Region | B14: US (baseline) | C14: US is cheapest. Other regions add a rough uplift - see the Rates tab.
A15: Which machine? | B15: Auto - cheapest that fits | C15: Leave on Auto and the sheet finds the cheapest one that fits.
A16: >> Pricing model | C16: Spot is cheapest but can be interrupted. Commitment needs a 1-year contract. | D16: =IF($B$16="",Simple_Calc!$C$23,$B$16) -> On-demand (pay as you go) | E16: =IF($B$16="","Simple_Calc","your entry") -> Simple_Calc
A17: >> Hours running per day | C17: 24 means always on. 8 means office hours only. | D17: =IF($B$17="",Simple_Calc!$C$18,$B$17) -> 24 | E17: =IF($B$17="","Simple_Calc","your entry") -> Simple_Calc
A18: >> Days running per month | C18: 30.42 is the average month. Use 22 for weekdays only. | D18: =IF($B$18="",Simple_Calc!$C$19,$B$18) -> 30.42 | E18: =IF($B$18="","Simple_Calc","your entry") -> Simple_Calc
A20: STEP 3 - STORAGE AND DATA
A21: >> Disk storage per copy (GB) | C21: Room for the model files, logs and scratch space. | D21: =IF($B$21="",Simple_Calc!$C$17,$B$21) -> 500 | E21: =IF($B$21="","Simple_Calc","your entry") -> Simple_Calc
A22: Disk type | B22: Balanced SSD (recommended) | C22: Balanced SSD suits almost everyone.
A23: >> Data sent out to users (GB per month) | C23: Only data leaving the cloud is charged. Text answers are small; audio and video are not. | D23: =IF($B$23="",Simple_Calc!$C$21,$B$23) -> 2000 | E23: =IF($B$23="","Simple_Calc","your entry") -> Simple_Calc
A25: STEP 4 - MANAGED PLATFORM
A26: >> Use a managed AI platform? | C26: Vertex AI or Azure ML do the plumbing for you and add about 25% to compute. | D26: =IF($B$26="",Simple_Calc!$C$24,$B$26) -> No - plain virtual machines | E26: =IF($B$26="","Simple_Calc","your entry") -> Simple_Calc
A28: STEP 5 - SUPPORT AND LABOUR (the people who keep it running)
A29: Recommended support level | B29: =IF($D$6<=Rates!$B$85,IF($D$6<=Rates!$B$84,Rates!$A$80,Rates!$A$81),Rates!$A$82) -> Medium | C29: Based on your model size. Low up to 13B, Medium up to 70B, High above that.
A30: Support level to use | B30: Use the recommendation | C30: Keep the recommendation, or override it with Low, Medium or High.
A31: Engineer hours per month | B31: =IF($B$32="",INDEX(Rates!$B$80:$B$82,MATCH($B$128,Rates!$A$80:$A$82,0)),$B$32) -> 60 | C31: Comes from the table on the Rates tab: Low 20, Medium 60, High 160 hours.
A32: Override the hours (optional) | C32: Leave this blank to use the table above. Type a number to use your own.
A33: Engineer cost per hour ($) | B33: 116 | C33: Your blended support rate.
A35: STEP 6 - YOUR ESTIMATE
A36: Recommended machine | B36: =IF($B$122=0,"none available",INDEX(GPU_Price_List!$H$5:$H$35,$B$121)) -> Standard_NC40ads_H100_v5
A37: Cloud | B37: =IF($B$122=0,"-",INDEX(GPU_Price_List!$C$5:$C$35,$B$121)) -> Microsoft Azure
A38: GPU | B38: =IF($B$122=0,"-",INDEX(GPU_Price_List!$D$5:$D$35,$B$121)) -> NVIDIA H100 NVL
A39: GPUs per machine | B39: =IF($B$122=0,0,INDEX(GPU_Price_List!$F$5:$F$35,$B$121)) -> 1
A40: Total GPU memory per machine (GB) | B40: =IF($B$122=0,0,INDEX(GPU_Price_List!$G$5:$G$35,$B$121)) -> 94
A41: vCPU per machine | B41: =IF($B$122=0,0,INDEX(GPU_Price_List!$I$5:$I$35,$B$121)) -> 40
A42: System RAM per machine (GB) | B42: =IF($B$122=0,0,INDEX(GPU_Price_List!$J$5:$J$35,$B$121)) -> 320
A43: US list price ($/hour) | B43: =IF($B$122=0,0,INDEX(GPU_Price_List!$K$5:$K$35,$B$121)) -> 6.98
A44: Your rate after region and pricing model ($/hour) | B44: =IF($B$122=0,0,INDEX(GPU_Price_List!$T$5:$T$35,$B$121)*$B$124) -> 6.98
A45: Hours billed per month | B45: =$D$17*$D$18 -> 730.08
...

Sheet Inference
A1: Inference sizing - how much traffic can it actually serve?
A2: The other tabs ask whether a model FITS on a machine. This one asks whether the machine is FAST ENOUGH, and works out how many machines your traffic needs.
A3: Fill in the yellow boxes. Turn the first one off and the rest of the workbook behaves exactly as before.
A5: 1. YOUR TRAFFIC
A6: Size the machines for this traffic? | B6: Yes - size the machines for this traffic | C6: Turn this off to go back to memory-only sizing.
A7: Requests per month | B7: 500000 | C7: A question, a summary, a completion - one round trip.
A8: Input tokens per request (the prompt) | B8: 800 | C8: Roughly 600 words. Add a lot if you paste in documents.
A9: Output tokens per request (the answer) | B9: 400 | C9: Roughly 300 words. This is the expensive half.
A10: Peak-to-average factor | B10: 3 | C10: Traffic is never flat. 3 means the busiest hour is 3x the average.
A12: 2. WHAT THAT DEMANDS
A13: Output tokens per month | B13: =$B$7*$B$9 -> 200000000
A14: Work per request in output-token equivalents | B14: =$B$9+$B$8/Rates!$B$110 -> 480 | C14: Prompt tokens are cheaper to process, so they count for less
A15: Average tokens per second needed | B15: =IFERROR($B$7*$B$14/(Calculator!$D$17*Calculator!$D$18*3600),0) -> 91.314194 | C15: Spread evenly over the hours you chose on the Calculator
A16: PEAK tokens per second needed | B16: =IF($B$6=Rates!$I$46,0,$B$15*$B$10) -> 273.94258 | C16: This is the number the machines are sized against
A18: 3. WHAT THE CHOSEN MACHINE DELIVERS
A19: Machine the Calculator picked | B19: =Calculator!$B$36 -> Standard_NC40ads_H100_v5
A20: GPUs x memory bandwidth (GB/s) | B20: =IF(Calculator!$B$122=0,0,INDEX(GPU_Price_List!$AA$5:$AA$35,Calculator!$B$121)) -> 3900 | C20: Generating a token means reading the whole model out of memory once
A21: Model weights to read per token (GB) | B21: =Calculator!$B$129 -> 70
A22: Output tokens per second, one machine | B22: =IF(Calculator!$B$122=0,0,INDEX(GPU_Price_List!$AB$5:$AB$35,Calculator!$B$121)) -> 624 | C22: With batching and utilisation from the Rates tab, section J
A23: Machines the peak load needs | B23: =Calculator!$B$130 -> 1
A24: Machines the estimate is using | B24: =Calculator!$D$9 -> 1 | C24: The greater of your copies and the machines the traffic needs
A25: Speed for a single user (tokens/sec) | B25: =IFERROR($B$20/$B$21*Rates!$B$109,0) -> 39 | C25: Around 20 or more feels like fast typing. Below 10 feels slow.
A26: Headroom at peak | B26: =IFERROR($B$22*$B$24/$B$16-1,0) -> 1.2778496 | C26: How much spare capacity is left when traffic peaks
A28: 4. UNIT ECONOMICS
A29: Total cost per month (from the Calculator) | B29: =Calculator!$B$53 -> 12261.758
A30: Million output tokens served per month | B30: =$B$13/1000000 -> 200
A31: Cost per million output tokens | B31: =IFERROR($B$29/$B$30,0) -> 61.308792 | C31: Compare this directly with a pay-per-token API price
A32: Cost per 1,000 requests | B32: =IFERROR($B$29/$B$7*1000,0) -> 24.523517
A33: Cost per request | B33: =IFERROR($B$29/$B$7,0) -> 0.024523517
A35: Verdict | B35: =IF($B$6=Rates!$I$46,"Inference sizing is switched off. The workbook is sizing on memory only.",IF(Calculator!$B$122=0,"No machine has enough memory for this model yet - fix that on the Calculator first.",IF($B$23>1,"This load needs "&$B$23&" of these machines to keep up at peak. "&"One machine generates about "&TEXT($B$22,"#,##0")&" tokens a second and the peak needs "&TEXT($B$16,"#,##0")&". The cost above already includes all "&$B$23&".","One machine is enough: it generates about "&TEXT($B$22,"#,##0")&" tokens a second against a peak need of "&TEXT($B$16,"#,##0")&"."))) -> One machine is enough: it generates about 624 tokens a second against a peak need of 274.
A39: How the throughput number is worked out, and where it is weakest:
A40: - Generating one token requires reading every weight in the model out of GPU memory. So tokens per second is roughly GPU memory bandwidth divided by model size, multiplied by the batching gain and the utilisation figure on the Rates tab.
A41: - That is a bandwidth model, not a benchmark. Real throughput also depends on the serving software, sequence lengths, and how evenly requests arrive. Treat it as accurate to within a factor of about two, and measure before you commit.
A42: - The batching gain of 16 assumes a modern server such as vLLM or TensorRT-LLM with continuous batching. A naive one-request-at-a-time setup is closer to 1, which changes the answer enormously.
A43: - Long prompts and long context windows grow the conversation cache, which eats memory and slows decode. This model does not capture that - raise the headroom percentage on the Calculator if you serve long context.
A44: - Cost per million tokens counts output tokens only, which is the convention most API price lists use.
A45: - Machines are sized on the peak, so the spare capacity sits idle most of the month. That is what the headroom row shows.

Sheet Comparison
A1: Side-by-side: Google Cloud vs Microsoft Azure
A2: Both columns answer the same question: what is the cheapest machine on that cloud that is big enough for the model set up on the Calculator tab? Change the Calculator and this updates.
A4: What we are comparing | B4: Google Cloud | C4: Microsoft Azure | D4: Which is cheaper
A5: Cheapest machine that fits | B5: =IF($B$62=0,"-",INDEX(GPU_Price_List!$H$5:$H$35,$B$60)) -> g2-standard-96 | C5: =IF($B$63=0,"-",INDEX(GPU_Price_List!$H$5:$H$35,$B$61)) -> Standard_NC40ads_H100_v5
A6: GPU | B6: =IF($B$62=0,"-",INDEX(GPU_Price_List!$D$5:$D$35,$B$60)) -> NVIDIA L4 | C6: =IF($B$63=0,"-",INDEX(GPU_Price_List!$D$5:$D$35,$B$61)) -> NVIDIA H100 NVL
A7: GPUs per machine | B7: =IF($B$62=0,0,INDEX(GPU_Price_List!$F$5:$F$35,$B$60)) -> 8 | C7: =IF($B$63=0,0,INDEX(GPU_Price_List!$F$5:$F$35,$B$61)) -> 1
A8: Total GPU memory (GB) | B8: =IF($B$62=0,0,INDEX(GPU_Price_List!$G$5:$G$35,$B$60)) -> 192 | C8: =IF($B$63=0,0,INDEX(GPU_Price_List!$G$5:$G$35,$B$61)) -> 94 | D8: Must be at least the memory the model needs
A9: vCPU | B9: =IF($B$62=0,0,INDEX(GPU_Price_List!$I$5:$I$35,$B$60)) -> 96 | C9: =IF($B$63=0,0,INDEX(GPU_Price_List!$I$5:$I$35,$B$61)) -> 40
A10: System RAM (GB) | B10: =IF($B$62=0,0,INDEX(GPU_Price_List!$J$5:$J$35,$B$60)) -> 384 | C10: =IF($B$63=0,0,INDEX(GPU_Price_List!$J$5:$J$35,$B$61)) -> 320
A11: US list price ($/hour) | B11: =IF($B$62=0,0,INDEX(GPU_Price_List!$K$5:$K$35,$B$60)) -> 8.0033 | C11: =IF($B$63=0,0,INDEX(GPU_Price_List!$K$5:$K$35,$B$61)) -> 6.98
A12: Your rate after region and pricing model ($/hour) | B12: =IF($B$62=0,0,INDEX(GPU_Price_List!$T$5:$T$35,$B$60)*$B$64) -> 8.0033 | C12: =IF($B$63=0,0,INDEX(GPU_Price_List!$T$5:$T$35,$B$61)*$B$65) -> 6.98
A13: Hours billed per month | B13: =Calculator!$B$45 -> 730.08 | C13: =Calculator!$B$45 -> 730.08
A14: Copies of the model | B14: =Calculator!$D$9 -> 1 | C14: =Calculator!$D$9 -> 1
A16: MONTHLY COST
A17: Compute | B17: =B12*B13*B14 -> 5843.0493 | C17: =C12*C13*C14 -> 5095.9584
A18: Disk storage | B18: =IF($B$62=0,0,Calculator!$D$21*Calculator!$D$9*INDEX(Rates!$B$6:$B$9,MATCH(Calculator!$B$22,Rates!$A$6:$A$9,0))) -> 50 | C18: =IF($B$63=0,0,Calculator!$D$21*Calculator!$D$9*INDEX(Rates!$C$6:$C$9,MATCH(Calculator!$B$22,Rates!$A$6:$A$9,0))) -> 40.5 | D18: Azure Premium SSD v2 is cheaper per GB than Google's Balanced disk
A19: Data transfer out | B19: =IF($B$62=0,0,Calculator!$B$126) -> 230.12 | C19: =IF($B$63=0,0,Calculator!$B$127) -> 165.3 | D19: Azure includes 100 GB free per month; Google Cloud includes 1 GB
A20: Managed platform uplift | B20: =IF(Calculator!$D$26=Rates!$F$46,B17*Rates!$B$34,0) -> 0 | C20: =IF(Calculator!$D$26=Rates!$F$46,C17*Rates!$B$35,0) -> 0
A21: Support and labour | B21: =Calculator!$B$52 -> 6960 | C21: =Calculator!$B$52 -> 6960 | D21: Same either way - the people cost does not depend on which cloud you pick
A22: TOTAL PER MONTH | B22: =SUM(B17:B21) -> 13083.169 | C22: =SUM(C17:C21) -> 12261.758
A23: TOTAL PER YEAR | B23: =B22*12 -> 156998.03 | C23: =C22*12 -> 147141.1
A25: Cheaper option | B25: =IF(AND($B$62=0,$B$63=0),"Neither cloud has a single machine with enough GPU memory. Use INT4, a smaller model, or plan on splitting the model across several machines.",IF($B$62=0,"Only Microsoft Azure has a machine big enough for this model.",IF($B$63=0,"Only Google Cloud has a machine big enough for this model.",IF(B22<C22,"Google Cloud saves about $"&TEXT(C22-B22,"#,##0")&" per month ("&TEXT(1-B22/C22,"0.0%")&" less)",IF(C22<B22,"Microsoft Azure saves about $"&TEXT(B22-C22,"#,##0")&" per month ("&TEXT(1-C22/B22,"0.0%")&" less)","The two are within a dollar of each other"))))) -> Microsoft Azure saves about $821 per month (6.3% less)
A27: Reading this fairly: a cheaper hourly rate is not the whole story. Azure sells single H100 and single A100 80GB machines, so small jobs need not rent an eight-GPU node. Google Cloud is usually cheaper per GPU-hour at the top end and its L4 machines are the best value for everyday inference. Availability, your existing contracts and which cloud your data already sits in often matter more than list price.
A31: PAY PER TOKEN INSTEAD - cheapest hosted model on each cloud
A32: Cheapest hosted model at your traffic | B32: =IFERROR(INDEX(Rates!$A$114:$A$134,MATCH(MIN(Rates!$J$114:$J$134),Rates!$J$114:$J$134,0)),"-") -> Gemini 2.5 Flash-Lite | C32: =IFERROR(INDEX(Rates!$A$114:$A$134,MATCH(MIN(Rates!$K$114:$K$134),Rates!$K$114:$K$134,0)),"-") -> GPT-5.6 Luna
A33: Token charges per month | B33: =MIN(Rates!$J$114:$J$134) -> 120 | C33: =MIN(Rates!$K$114:$K$134) -> 320
A34: Support and labour | B34: =Calculator!$B$69 -> 2320 | C34: =Calculator!$B$69 -> 2320 | D34: Running an API integration needs far fewer engineer hours than running machines
A35: TOTAL PER MONTH - pay per token | B35: =B33+B34 -> 2440 | C35: =C33+C34 -> 2640
A36: Self-hosting total per month | B36: =B22 -> 13083.169 | C36: =C22 -> 12261.758
A37: Cheaper approach on this cloud | B37: =IF(B35<B22,"Pay per token","Self-host") -> Pay per token | C37: =IF(C35<C22,"Pay per token","Self-host") -> Pay per token
A39: Cheapest of all four options | B39: =IF(Inference!$B$7<=0,"Enter your expected traffic on the Inference tab to compare against pay-per-token pricing.","Cheapest overall: "&IF(MIN($B$22,$C$22,$B$35,$C$35)=$B$35,"pay per token on Google Cloud using "&$B$32,IF(MIN($B$22,$C$22,$B$35,$C$35)=$C$35,"pay per token on Azure using "&$C$32,IF(MIN($B$22,$C$22,$B$35,$C$35)=$B$22,"self-hosting on Google Cloud on "&$B$5,"self-hosting on Azure on "&$C$5)))&" at about $"&TEXT(MIN($B$22,$C$22,$B$35,$C$35),"#,##0")&" per month, versus $"&TEXT(MAX($B$22,$C$22,$B$35,$C$35),"#,##0")&" for the most expensive of the four.") -> Cheapest overall: pay per token on Google Cloud using Gemini 2.5 Flash-Lite at about $2,440 per month, versus $13,083 for the most expensive of the four.
A42: Why pay-per-token usually wins at low volume and loses at high volume: a rented GPU costs the same whether it is busy or idle, so light traffic pays for mostly-idle hardware. A hosted model charges only for tokens used. Once traffic is heavy enough to keep your own machines busy, the per-token margin you are paying someone else starts to exceed the cost of the hardware. The crossover is usually further out than people expect - change the requests figure on the Inference tab to find yours.
A60: Engine - Google Cloud row | B60: =IFERROR(MATCH(MIN(GPU_Price_List!$X$5:$X$35),GPU_Price_List!$X$5:$X$35,0),0) -> 11
A61: Engine - Azure row | B61: =IFERROR(MATCH(MIN(GPU_Price_List!$Y$5:$Y$35),GPU_Price_List!$Y$5:$Y$35,0),0) -> 24
A62: Engine - GCP found? (1 = yes) | B62: =IF(MIN(GPU_Price_List!$X$5:$X$35)>=1000000000,0,1) -> 1
A63: Engine - Azure found? (1 = yes) | B63: =IF(MIN(GPU_Price_List!$Y$5:$Y$35)>=1000000000,0,1) -> 1
A64: Engine - GCP region uplift | B64: =INDEX(Rates!$B$21:$B$24,MATCH(Calculator!$B$14,Rates!$A$21:$A$24,0)) -> 1
A65: Engine - Azure region uplift | B65: =INDEX(Rates!$C$21:$C$24,MATCH(Calculator!$B$14,Rates!$A$21:$A$24,0)) -> 1

Sheet GPU_Price_List
A1: GPU Machine Price List - Google Cloud and Microsoft Azure, cheapest GPU first
A2: Sorted lowest tier (NVIDIA T4) to highest tier (NVIDIA B200). US-region list prices, August 2026. Columns T onward are used by the Calculator - please leave them alone.
T3: CALCULATOR ENGINE - these six columns react to the Calculator tab. Do not edit. | Z3: THROUGHPUT ENGINE - driven by the Inference tab. Do not edit.
A4: Tier | B4: Tier name | C4: Cloud | D4: GPU model | E4: GPU memory each (GB) | F4: GPUs per machine | G4: Total GPU memory (GB) | H4: Machine / VM size | I4: vCPU | J4: RAM (GB) | K4: On-demand $/hour | L4: Spot $/hour | M4: Spot rate source | N4: 1-Year commit $/hour | O4: On-demand $/month | P4: Good for | Q4: Price confidence | R4: Source | S4: Menu label | T4: Selected rate $/hour | U4: Cloud matches filter? | V4: Enough GPU memory? | W4: Rank - either cloud | X4: Rank - Google Cloud | Y4: Rank - Azure | Z4: GPU bandwidth each (GB/s) | AA4: Total bandwidth (GB/s) | AB4: Output tokens/sec per machine | AC4: Machines needed for the load | AD4: Cost to meet the load $/hour
A5: 1 | B5: T4 16 GB - entry level | C5: Microsoft Azure | D5: NVIDIA T4 | E5: 16 | F5: 1 | G5: =E5*F5 -> 16 | H5: Standard_NC4as_T4_v3 | I5: 4 | J5: 28 | K5: 0.526 | L5: 0.15254 | M5: Published spot rate | N5: =K5*IF(C5=Rates!$A$45,Rates!$B$29,Rates!$C$29) -> 0.3419 | O5: =K5*Rates!$B$30 -> 383.98 | P5: Small models, demos, dev boxes | Q5: Published list price | R5: Azure East US Linux pay-as-you-go (Vantage/CloudPrice) | S5: =C5&" | "&H5 -> Microsoft Azure | Standard_NC4as_T4_v3 | T5: =IF(Calculator!$D$16=Rates!$C$46,L5,IF(Calculator!$D$16=Rates!$C$47,N5,K5)) -> 0.526 | U5: =IF(OR(Calculator!$B$13=Rates!$A$47,Calculator!$B$13=C5),1,0) -> 1 | V5: =IF(G5>=Calculator!$B$10,1,0) -> 0 | W5: =IF(AND(U5=1,V5=1),AD5,1000000000) -> 1000000000 | X5: =IF(AND(C5=Rates!$A$45,V5=1),AD5,1000000000) -> 1000000000 | Y5: =IF(AND(C5=Rates!$A$46,V5=1),AD5,1000000000) -> 1000000000 | Z5: 320 | AA5: =Z5*F5 -> 320 | AB5: =IFERROR(AA5/Calculator!$B$129*Rates!$B$108*Rates!$B$109,0) -> 51.2 | AC5: =IF(Inference!$B$16<=0,1,IF(AB5<=0,1000000000,MAX(1,ROUNDUP(Inference!$B$16/AB5,0)))) -> 6 | AD5: =T5*AC5+AC5/1000000 -> 3.156006
A6: 1 | B6: T4 16 GB - entry level | C6: Google Cloud | D6: NVIDIA T4 | E6: 16 | F6: 1 | G6: =E6*F6 -> 16 | H6: n1-standard-4 + 1x T4 | I6: 4 | J6: 15 | K6: 0.54 | L6: =K6*IF(C6=Rates!$A$45,Rates!$B$28,Rates!$C$28) -> 0.1782 | M6: Estimated (cloud default factor) | N6: =K6*IF(C6=Rates!$A$45,Rates!$B$29,Rates!$C$29) -> 0.378 | O6: =K6*Rates!$B$30 -> 394.2 | P6: Small models, demos, dev boxes | Q6: Published list price | R6: GCP: n1-standard-4 $0.1900/hr + T4 $0.35/GPU/hr, us-central1 | S6: =C6&" | "&H6 -> Google Cloud | n1-standard-4 + 1x T4 | T6: =IF(Calculator!$D$16=Rates!$C$46,L6,IF(Calculator!$D$16=Rates!$C$47,N6,K6)) -> 0.54 | U6: =IF(OR(Calculator!$B$13=Rates!$A$47,Calculator!$B$13=C6),1,0) -> 1 | V6: =IF(G6>=Calculator!$B$10,1,0) -> 0 | W6: =IF(AND(U6=1,V6=1),AD6,1000000000) -> 1000000000 | X6: =IF(AND(C6=Rates!$A$45,V6=1),AD6,1000000000) -> 1000000000 | Y6: =IF(AND(C6=Rates!$A$46,V6=1),AD6,1000000000) -> 1000000000 | Z6: 320 | AA6: =Z6*F6 -> 320 | AB6: =IFERROR(AA6/Calculator!$B$129*Rates!$B$108*Rates!$B$109,0) -> 51.2 | AC6: =IF(Inference!$B$16<=0,1,IF(AB6<=0,1000000000,MAX(1,ROUNDUP(Inference!$B$16/AB6,0)))) -> 6 | AD6: =T6*AC6+AC6/1000000 -> 3.240006
A7: 1 | B7: T4 16 GB - entry level | C7: Google Cloud | D7: NVIDIA T4 | E7: 16 | F7: 1 | G7: =E7*F7 -> 16 | H7: n1-standard-8 + 1x T4 | I7: 8 | J7: 30 | K7: 0.73 | L7: =K7*IF(C7=Rates!$A$45,Rates!$B$28,Rates!$C$28) -> 0.2409 | M7: Estimated (cloud default factor) | N7: =K7*IF(C7=Rates!$A$45,Rates!$B$29,Rates!$C$29) -> 0.511 | O7: =K7*Rates!$B$30 -> 532.9 | P7: Small models with more CPU-side work | Q7: Published list price | R7: GCP: n1-standard-8 $0.3800/hr + T4 $0.35/GPU/hr, us-central1 | S7: =C7&" | "&H7 -> Google Cloud | n1-standard-8 + 1x T4 | T7: =IF(Calculator!$D$16=Rates!$C$46,L7,IF(Calculator!$D$16=Rates!$C$47,N7,K7)) -> 0.73 | U7: =IF(OR(Calculator!$B$13=Rates!$A$47,Calculator!$B$13=C7),1,0) -> 1 | V7: =IF(G7>=Calculator!$B$10,1,0) -> 0 | W7: =IF(AND(U7=1,V7=1),AD7,1000000000) -> 1000000000 | X7: =IF(AND(C7=Rates!$A$45,V7=1),AD7,1000000000) -> 1000000000 | Y7: =IF(AND(C7=Rates!$A$46,V7=1),AD7,1000000000) -> 1000000000 | Z7: 320 | AA7: =Z7*F7 -> 320 | AB7: =IFERROR(AA7/Calculator!$B$129*Rates!$B$108*Rates!$B$109,0) -> 51.2 | AC7: =IF(Inference!$B$16<=0,1,IF(AB7<=0,1000000000,MAX(1,ROUNDUP(Inference!$B$16/AB7,0)))) -> 6 | AD7: =T7*AC7+AC7/1000000 -> 4.380006
A8: 1 | B8: T4 16 GB - entry level | C8: Microsoft Azure | D8: NVIDIA T4 | E8: 16 | F8: 1 | G8: =E8*F8 -> 16 | H8: Standard_NC8as_T4_v3 | I8: 8 | J8: 56 | K8: 0.752 | L8: 0.256958 | M8: Published spot rate | N8: =K8*IF(C8=Rates!$A$45,Rates!$B$29,Rates!$C$29) -> 0.4888 | O8: =K8*Rates!$B$30 -> 548.96 | P8: Small models with more CPU-side work | Q8: Published list price | R8: Azure East US Linux pay-as-you-go (Vantage/CloudPrice) | S8: =C8&" | "&H8 -> Microsoft Azure | Standard_NC8as_T4_v3 | T8: =IF(Calculator!$D$16=Rates!$C$46,L8,IF(Calculator!$D$16=Rates!$C$47,N8,K8)) -> 0.752 | U8: =IF(OR(Calculator!$B$13=Rates!$A$47,Calculator!$B$13=C8),1,0) -> 1 | V8: =IF(G8>=Calculator!$B$10,1,0) -> 0 | W8: =IF(AND(U8=1,V8=1),AD8,1000000000) -> 1000000000 | X8: =IF(AND(C8=Rates!$A$45,V8=1),AD8,1000000000) -> 1000000000 | Y8: =IF(AND(C8=Rates!$A$46,V8=1),AD8,1000000000) -> 1000000000 | Z8: 320 | AA8: =Z8*F8 -> 320 | AB8: =IFERROR(AA8/Calculator!$B$129*Rates!$B$108*Rates!$B$109,0) -> 51.2 | AC8: =IF(Inference!$B$16<=0,1,IF(AB8<=0,1000000000,MAX(1,ROUNDUP(Inference!$B$16/AB8,0)))) -> 6 | AD8: =T8*AC8+AC8/1000000 -> 4.512006
A9: 1 | B9: T4 16 GB - entry level | C9: Google Cloud | D9: NVIDIA T4 | E9: 16 | F9: 2 | G9: =E9*F9 -> 32 | H9: n1-standard-8 + 2x T4 | I9: 8 | J9: 30 | K9: 1.08 | L9: =K9*IF(C9=Rates!$A$45,Rates!$B$28,Rates!$C$28) -> 0.3564 | M9: Estimated (cloud default factor) | N9: =K9*IF(C9=Rates!$A$45,Rates!$B$29,Rates!$C$29) -> 0.756 | O9: =K9*Rates!$B$30 -> 788.4 | P9: Mid-size model split over 2 cheap GPUs | Q9: Published list price | R9: GCP: n1-standard-8 $0.3800/hr + 2x T4 @ $0.35/GPU/hr, us-central1 | S9: =C9&" | "&H9 -> Google Cloud | n1-standard-8 + 2x T4 | T9: =IF(Calculator!$D$16=Rates!$C$46,L9,IF(Calculator!$D$16=Rates!$C$47,N9,K9)) -> 1.08 | U9: =IF(OR(Calculator!$B$13=Rates!$A$47,Calculator!$B$13=C9),1,0) -> 1 | V9: =IF(G9>=Calculator!$B$10,1,0) -> 0 | W9: =IF(AND(U9=1,V9=1),AD9,1000000000) -> 1000000000 | X9: =IF(AND(C9=Rates!$A$45,V9=1),AD9,1000000000) -> 1000000000 | Y9: =IF(AND(C9=Rates!$A$46,V9=1),AD9,1000000000) -> 1000000000 | Z9: 320 | AA9: =Z9*F9 -> 640 | AB9: =IFERROR(AA9/Calculator!$B$129*Rates!$B$108*Rates!$B$109,0) -> 102.4 | AC9: =IF(Inference!$B$16<=0,1,IF(AB9<=0,1000000000,MAX(1,ROUNDUP(Inference!$B$16/AB9,0)))) -> 3 | AD9: =T9*AC9+AC9/1000000 -> 3.240003
A10: 2 | B10: L4 / A10 24 GB - inference workhorse | C10: Google Cloud | D10: NVIDIA L4 | E10: 24 | F10: 1 | G10: =E10*F10 -> 24 | H10: g2-standard-4 | I10: 4 | J10: 16 | K10: 0.7068 | L10: 0.2818 | M10: Published spot rate | N10: =K10*IF(C10=Rates!$A$45,Rates!$B$29,Rates!$C$29) -> 0.49476 | O10: =K10*Rates!$B$30 -> 515.964 | P10: Best value for everyday inference | Q10: Published list price | R10: GCP accelerator-optimized pricing, us-central1 | S10: =C10&" | "&H10 -> Google Cloud | g2-standard-4 | T10: =IF(Calculator!$D$16=Rates!$C$46,L10,IF(Calculator!$D$16=Rates!$C$47,N10,K10)) -> 0.7068 | U10: =IF(OR(Calculator!$B$13=Rates!$A$47,Calculator!$B$13=C10),1,0) -> 1 | V10: =IF(G10>=Calculator!$B$10,1,0) -> 0 | W10: =IF(AND(U10=1,V10=1),AD10,1000000000) -> 1000000000 | X10: =IF(AND(C10=Rates!$A$45,V10=1),AD10,1000000000) -> 1000000000 | Y10: =IF(AND(C10=Rates!$A$46,V10=1),AD10,1000000000) -> 1000000000 | Z10: 300 | AA10: =Z10*F10 -> 300 | AB10: =IFERROR(AA10/Calculator!$B$129*Rates!$B$108*Rates!$B$109,0) -> 48 | AC10: =IF(Inference!$B$16<=0,1,IF(AB10<=0,1000000000,MAX(1,ROUNDUP(Inference!$B$16/AB10,0)))) -> 6 | AD10: =T10*AC10+AC10/1000000 -> 4.240806
A11: 2 | B11: L4 / A10 24 GB - inference workhorse | C11: Google Cloud | D11: NVIDIA L4 | E11: 24 | F11: 1 | G11: =E11*F11 -> 24 | H11: g2-standard-8 | I11: 8 | J11: 32 | K11: 0.8536 | L11: 0.3406 | M11: Published spot rate | N11: =K11*IF(C11=Rates!$A$45,Rates!$B$29,Rates!$C$29) -> 0.59752 | O11: =K11*Rates!$B$30 -> 623.128 | P11: Everyday inference, more RAM | Q11: Published list price | R11: GCP accelerator-optimized pricing, us-central1 | S11: =C11&" | "&H11 -> Google Cloud | g2-standard-8 | T11: =IF(Calculator!$D$16=Rates!$C$46,L11,IF(Calculator!$D$16=Rates!$C$47,N11,K11)) -> 0.8536 | U11: =IF(OR(Calculator!$B$13=Rates!$A$47,Calculator!$B$13=C11),1,0) -> 1 | V11: =IF(G11>=Calculator!$B$10,1,0) -> 0 | W11: =IF(AND(U11=1,V11=1),AD11,1000000000) -> 1000000000 | X11: =IF(AND(C11=Rates!$A$45,V11=1),AD11,1000000000) -> 1000000000 | Y11: =IF(AND(C11=Rates!$A$46,V11=1),AD11,1000000000) -> 1000000000 | Z11: 300 | AA11: =Z11*F11 -> 300 | AB11: =IFERROR(AA11/Calculator!$B$129*Rates!$B$108*Rates!$B$109,0) -> 48 | AC11: =IF(Inference!$B$16<=0,1,IF(AB11<=0,1000000000,MAX(1,ROUNDUP(Inference!$B$16/AB11,0)))) -> 6 | AD11: =T11*AC11+AC11/1000000 -> 5.121606
A12: 2 | B12: L4 / A10 24 GB - inference workhorse | C12: Google Cloud | D12: NVIDIA L4 | E12: 24 | F12: 2 | G12: =E12*F12 -> 48 | H12: g2-standard-24 | I12: 24 | J12: 96 | K12: 2.0008 | L12: 0.7986 | M12: Published spot rate | N12: =K12*IF(C12=Rates!$A$45,Rates!$B$29,Rates!$C$29) -> 1.40056 | O12: =K12*Rates!$B$30 -> 1460.584 | P12: Two GPUs for larger models | Q12: Published list price | R12: GCP accelerator-optimized pricing, us-central1 | S12: =C12&" | "&H12 -> Google Cloud | g2-standard-24 | T12: =IF(Calculator!$D$16=Rates!$C$46,L12,IF(Calculator!$D$16=Rates!$C$47,N12,K12)) -> 2.0008 | U12: =IF(OR(Calculator!$B$13=Rates!$A$47,Calculator!$B$13=C12),1,0) -> 1 | V12: =IF(G12>=Calculator!$B$10,1,0) -> 0 | W12: =IF(AND(U12=1,V12=1),AD12,1000000000) -> 1000000000 | X12: =IF(AND(C12=Rates!$A$45,V12=1),AD12,1000000000) -> 1000000000 | Y12: =IF(AND(C12=Rates!$A$46,V12=1),AD12,1000000000) -> 1000000000 | Z12: 300 | AA12: =Z12*F12 -> 600 | AB12: =IFERROR(AA12/Calculator!$B$129*Rates!$B$108*Rates!$B$109,0) -> 96 | AC12: =IF(Inference!$B$16<=0,1,IF(AB12<=0,1000000000,MAX(1,ROUNDUP(Inference!$B$16/AB12,0)))) -> 3 | AD12: =T12*AC12+AC12/1000000 -> 6.002403
A13: 2 | B13: L4 / A10 24 GB - inference workhorse | C13: Microsoft Azure | D13: NVIDIA A10 | E13: 24 | F13: 1 | G13: =E13*F13 -> 24 | H13: Standard_NV36ads_A10_v5 | I13: 36 | J13: 440 | K13: 3.2 | L13: 0.59136 | M13: Published spot rate | N13: =K13*IF(C13=Rates!$A$45,Rates!$B$29,Rates!$C$29) -> 2.08 | O13: =K13*Rates!$B$30 -> 2336 | P13: Inference plus heavy CPU pre/post-processing | Q13: Published list price | R13: Azure East US Linux pay-as-you-go (Vantage) | S13: =C13&" | "&H13 -> Microsoft Azure | Standard_NV36ads_A10_v5 | T13: =IF(Calculator!$D$16=Rates!$C$46,L13,IF(Calculator!$D$16=Rates!$C$47,N13,K13)) -> 3.2 | U13: =IF(OR(Calculator!$B$13=Rates!$A$47,Calculator!$B$13=C13),1,0) -> 1 | V13: =IF(G13>=Calculator!$B$10,1,0) -> 0 | W13: =IF(AND(U13=1,V13=1),AD13,1000000000) -> 1000000000 | X13: =IF(AND(C13=Rates!$A$45,V13=1),AD13,1000000000) -> 1000000000 | Y13: =IF(AND(C13=Rates!$A$46,V13=1),AD13,1000000000) -> 1000000000 | Z13: 600 | AA13: =Z13*F13 -> 600 | AB13: =IFERROR(AA13/Calculator!$B$129*Rates!$B$108*Rates!$B$109,0) -> 96 | AC13: =IF(Inference!$B$16<=0,1,IF(AB13<=0,1000000000,MAX(1,ROUNDUP(Inference!$B$16/AB13,0)))) -> 3 | AD13: =T13*AC13+AC13/1000000 -> 9.600003
A14: 2 | B14: L4 / A10 24 GB - inference workhorse | C14: Google Cloud | D14: NVIDIA L4 | E14: 24 | F14: 4 | G14: =E14*F14 -> 96 | H14: g2-standard-48 | I14: 48 | J14: 192 | K14: 4.0017 | L14: 1.5972 | M14: Published spot rate | N14: =K14*IF(C14=Rates!$A$45,Rates!$B$29,Rates!$C$29) -> 2.80119 | O14: =K14*Rates!$B$30 -> 2921.241 | P14: Four GPUs, high throughput serving | Q14: Published list price | R14: GCP accelerator-optimized pricing, us-central1 | S14: =C14&" | "&H14 -> Google Cloud | g2-standard-48 | T14: =IF(Calculator!$D$16=Rates!$C$46,L14,IF(Calculator!$D$16=Rates!$C$47,N14,K14)) -> 4.0017 | U14: =IF(OR(Calculator!$B$13=Rates!$A$47,Calculator!$B$13=C14),1,0) -> 1 | V14: =IF(G14>=Calculator!$B$10,1,0) -> 1 | W14: =IF(AND(U14=1,V14=1),AD14,1000000000) -> 8.003402 | X14: =IF(AND(C14=Rates!$A$45,V14=1),AD14,1000000000) -> 8.003402 | Y14: =IF(AND(C14=Rates!$A$46,V14=1),AD14,1000000000) -> 1000000000 | Z14: 300 | AA14: =Z14*F14 -> 1200 | AB14: =IFERROR(AA14/Calculator!$B$129*Rates!$B$108*Rates!$B$109,0) -> 192 | AC14: =IF(Inference!$B$16<=0,1,IF(AB14<=0,1000000000,MAX(1,ROUNDUP(Inference!$B$16/AB14,0)))) -> 2 | AD14: =T14*AC14+AC14/1000000 -> 8.003402
A15: 2 | B15: L4 / A10 24 GB - inference workhorse | C15: Google Cloud | D15: NVIDIA L4 | E15: 24 | F15: 8 | G15: =E15*F15 -> 192 | H15: g2-standard-96 | I15: 96 | J15: 384 | K15: 8.0033 | L15: 3.1945 | M15: Published spot rate | N15: =K15*IF(C15=Rates!$A$45,Rates!$B$29,Rates!$C$29) -> 5.60231 | O15: =K15*Rates!$B$30 -> 5842.409 | P15: Eight GPUs, high throughput serving | Q15: Published list price | R15: GCP accelerator-optimized pricing, us-central1 | S15: =C15&" | "&H15 -> Google Cloud | g2-standard-96 | T15: =IF(Calculator!$D$16=Rates!$C$46,L15,IF(Calculator!$D$16=Rates!$C$47,N15,K15)) -> 8.0033 | U15: =IF(OR(Calculator!$B$13=Rates!$A$47,Calculator!$B$13=C15),1,0) -> 1 | V15: =IF(G15>=Calculator!$B$10,1,0) -> 1 | W15: =IF(AND(U15=1,V15=1),AD15,1000000000) -> 8.003301 | X15: =IF(AND(C15=Rates!$A$45,V15=1),AD15,1000000000) -> 8.003301 | Y15: =IF(AND(C15=Rates!$A$46,V15=1),AD15,1000000000) -> 1000000000 | Z15: 300 | AA15: =Z15*F15 -> 2400 | AB15: =IFERROR(AA15/Calculator!$B$129*Rates!$B$108*Rates!$B$109,0) -> 384 | AC15: =IF(Inference!$B$16<=0,1,IF(AB15<=0,1000000000,MAX(1,ROUNDUP(Inference!$B$16/AB15,0)))) -> 1 | AD15: =T15*AC15+AC15/1000000 -> 8.003301
A16: 3 | B16: A100 40 GB - training and large inference | C16: Google Cloud | D16: NVIDIA A100 40GB | E16: 40 | F16: 1 | G16: =E16*F16 -> 40 | H16: a2-highgpu-1g | I16: 12 | J16: 85 | K16: 3.6734 | L16: 1.443 | M16: Published spot rate | N16: =K16*IF(C16=Rates!$A$45,Rates!$B$29,Rates!$C$29) -> 2.57138 | O16: =K16*Rates!$B$30 -> 2681.582 | P16: Entry point for single-GPU A100 work | Q16: Published list price | R16: GCP accelerator-optimized pricing, us-central1 | S16: =C16&" | "&H16 -> Google Cloud | a2-highgpu-1g | T16: =IF(Calculator!$D$16=Rates!$C$46,L16,IF(Calculator!$D$16=Rates!$C$47,N16,K16)) -> 3.6734 | U16: =IF(OR(Calculator!$B$13=Rates!$A$47,Calculator!$B$13=C16),1,0) -> 1 | V16: =IF(G16>=Calculator!$B$10,1,0) -> 0 | W16: =IF(AND(U16=1,V16=1),AD16,1000000000) -> 1000000000 | X16: =IF(AND(C16=Rates!$A$45,V16=1),AD16,1000000000) -> 1000000000 | Y16: =IF(AND(C16=Rates!$A$46,V16=1),AD16,1000000000) -> 1000000000 | Z16: 1555 | AA16: =Z16*F16 -> 1555 | AB16: =IFERROR(AA16/Calculator!$B$129*Rates!$B$108*Rates!$B$109,0) -> 248.8 | AC16: =IF(Inference!$B$16<=0,1,IF(AB16<=0,1000000000,MAX(1,ROUNDUP(Inference!$B$16/AB16,0)))) -> 2 | AD16: =T16*AC16+AC16/1000000 -> 7.346802
A17: 3 | B17: A100 40 GB - training and large inference | C17: Google Cloud | D17: NVIDIA A100 40GB | E17: 40 | F17: 2 | G17: =E17*F17 -> 80 | H17: a2-highgpu-2g | I17: 24 | J17: 170 | K17: 7.3468 | L17: 2.8859 | M17: Published spot rate | N17: =K17*IF(C17=Rates!$A$45,Rates!$B$29,Rates!$C$29) -> 5.14276 | O17: =K17*Rates!$B$30 -> 5363.164 | P17: Fine-tuning mid-size models | Q17: Published list price | R17: GCP accelerator-optimized pricing, us-central1 | S17: =C17&" | "&H17 -> Google Cloud | a2-highgpu-2g | T17: =IF(Calculator!$D$16=Rates!$C$46,L17,IF(Calculator!$D$16=Rates!$C$47,N17,K17)) -> 7.3468 | U17: =IF(OR(Calculator!$B$13=Rates!$A$47,Calculator!$B$13=C17),1,0) -> 1 | V17: =IF(G17>=Calculator!$B$10,1,0) -> 0 | W17: =IF(AND(U17=1,V17=1),AD17,1000000000) -> 1000000000 | X17: =IF(AND(C17=Rates!$A$45,V17=1),AD17,1000000000) -> 1000000000 | Y17: =IF(AND(C17=Rates!$A$46,V17=1),AD17,1000000000) -> 1000000000 | Z17: 1555 | AA17: =Z17*F17 -> 3110 | AB17: =IFERROR(AA17/Calculator!$B$129*Rates!$B$108*Rates!$B$109,0) -> 497.6 | AC17: =IF(Inference!$B$16<=0,1,IF(AB17<=0,1000000000,MAX(1,ROUNDUP(Inference!$B$16/AB17,0)))) -> 1 | AD17: =T17*AC17+AC17/1000000 -> 7.346801
A18: 3 | B18: A100 40 GB - training and large inference | C18: Google Cloud | D18: NVIDIA A100 40GB | E18: 40 | F18: 4 | G18: =E18*F18 -> 160 | H18: a2-highgpu-4g | I18: 48 | J18: 340 | K18: 14.6935 | L18: 5.7718 | M18: Published spot rate | N18: =K18*IF(C18=Rates!$A$45,Rates!$B$29,Rates!$C$29) -> 10.28545 | O18: =K18*Rates!$B$30 -> 10726.255 | P18: Fine-tuning and multi-GPU serving | Q18: Published list price | R18: GCP accelerator-optimized pricing, us-central1 | S18: =C18&" | "&H18 -> Google Cloud | a2-highgpu-4g | T18: =IF(Calculator!$D$16=Rates!$C$46,L18,IF(Calculator!$D$16=Rates!$C$47,N18,K18)) -> 14.6935 | U18: =IF(OR(Calculator!$B$13=Rates!$A$47,Calculator!$B$13=C18),1,0) -> 1 | V18: =IF(G18>=Calculator!$B$10,1,0) -> 1 | W18: =IF(AND(U18=1,V18=1),AD18,1000000000) -> 14.693501 | X18: =IF(AND(C18=Rates!$A$45,V18=1),AD18,1000000000) -> 14.693501 | Y18: =IF(AND(C18=Rates!$A$46,V18=1),AD18,1000000000) -> 1000000000 | Z18: 1555 | AA18: =Z18*F18 -> 6220 | AB18: =IFERROR(AA18/Calculator!$B$129*Rates!$B$108*Rates!$B$109,0) -> 995.2 | AC18: =IF(Inference!$B$16<=0,1,IF(AB18<=0,1000000000,MAX(1,ROUNDUP(Inference!$B$16/AB18,0)))) -> 1 | AD18: =T18*AC18+AC18/1000000 -> 14.693501
A19: 3 | B19: A100 40 GB - training and large inference | C19: Google Cloud | D19: NVIDIA A100 40GB | E19: 40 | F19: 8 | G19: =E19*F19 -> 320 | H19: a2-highgpu-8g | I19: 96 | J19: 680 | K19: 29.3871 | L19: 11.5436 | M19: Published spot rate | N19: =K19*IF(C19=Rates!$A$45,Rates!$B$29,Rates!$C$29) -> 20.57097 | O19: =K19*Rates!$B$30 -> 21452.583 | P19: Lowest-cost 8x A100 node | Q19: Published list price | R19: GCP accelerator-optimized pricing, us-central1 | S19: =C19&" | "&H19 -> Google Cloud | a2-highgpu-8g | T19: =IF(Calculator!$D$16=Rates!$C$46,L19,IF(Calculator!$D$16=Rates!$C$47,N19,K19)) -> 29.3871 | U19: =IF(OR(Calculator!$B$13=Rates!$A$47,Calculator!$B$13=C19),1,0) -> 1 | V19: =IF(G19>=Calculator!$B$10,1,0) -> 1 | W19: =IF(AND(U19=1,V19=1),AD19,1000000000) -> 29.387101 | X19: =IF(AND(C19=Rates!$A$45,V19=1),AD19,1000000000) -> 29.387101 | Y19: =IF(AND(C19=Rates!$A$46,V19=1),AD19,1000000000) -> 1000000000 | Z19: 1555 | AA19: =Z19*F19 -> 12440 | AB19: =IFERROR(AA19/Calculator!$B$129*Rates!$B$108*Rates!$B$109,0) -> 1990.4 | AC19: =IF(Inference!$B$16<=0,1,IF(AB19<=0,1000000000,MAX(1,ROUNDUP(Inference!$B$16/AB19,0)))) -> 1 | AD19: =T19*AC19+AC19/1000000 -> 29.387101
A20: 3 | B20: A100 40 GB - training and large inference | C20: Google Cloud | D20: NVIDIA A100 40GB | E20: 40 | F20: 16 | G20: =E20*F20 -> 640 | H20: a2-megagpu-16g | I20: 96 | J20: 1360 | K20: 55.7395 | L20: 21.8738 | M20: Published spot rate | N20: =K20*IF(C20=Rates!$A$45,Rates!$B$29,Rates!$C$29) -> 39.01765 | O20: =K20*Rates!$B$30 -> 40689.835 | P20: 16 GPUs in one machine | Q20: Published list price | R20: GCP accelerator-optimized pricing, us-central1 | S20: =C20&" | "&H20 -> Google Cloud | a2-megagpu-16g | T20: =IF(Calculator!$D$16=Rates!$C$46,L20,IF(Calculator!$D$16=Rates!$C$47,N20,K20)) -> 55.7395 | U20: =IF(OR(Calculator!$B$13=Rates!$A$47,Calculator!$B$13=C20),1,0) -> 1 | V20: =IF(G20>=Calculator!$B$10,1,0) -> 1 | W20: =IF(AND(U20=1,V20=1),AD20,1000000000) -> 55.739501 | X20: =IF(AND(C20=Rates!$A$45,V20=1),AD20,1000000000) -> 55.739501 | Y20: =IF(AND(C20=Rates!$A$46,V20=1),AD20,1000000000) -> 1000000000 | Z20: 1555 | AA20: =Z20*F20 -> 24880 | AB20: =IFERROR(AA20/Calculator!$B$129*Rates!$B$108*Rates!$B$109,0) -> 3980.8 | AC20: =IF(Inference!$B$16<=0,1,IF(AB20<=0,1000000000,MAX(1,ROUNDUP(Inference!$B$16/AB20,0)))) -> 1 | AD20: =T20*AC20+AC20/1000000 -> 55.739501
A21: 4 | B21: A100 80 GB - larger models per GPU | C21: Microsoft Azure | D21: NVIDIA A100 80GB | E21: 80 | F21: 1 | G21: =E21*F21 -> 80 | H21: Standard_NC24ads_A100_v4 | I21: 24 | J21: 220 | K21: 3.673 | L21: 0.67877 | M21: Published spot rate | N21: =K21*IF(C21=Rates!$A$45,Rates!$B$29,Rates!$C$29) -> 2.38745 | O21: =K21*Rates!$B$30 -> 2681.29 | P21: Cheapest single 80 GB GPU on Azure | Q21: Published list price | R21: Azure East US Linux pay-as-you-go (Vantage) | S21: =C21&" | "&H21 -> Microsoft Azure | Standard_NC24ads_A100_v4 | T21: =IF(Calculator!$D$16=Rates!$C$46,L21,IF(Calculator!$D$16=Rates!$C$47,N21,K21)) -> 3.673 | U21: =IF(OR(Calculator!$B$13=Rates!$A$47,Calculator!$B$13=C21),1,0) -> 1 | V21: =IF(G21>=Calculator!$B$10,1,0) -> 0 | W21: =IF(AND(U21=1,V21=1),AD21,1000000000) -> 1000000000 | X21: =IF(AND(C21=Rates!$A$45,V21=1),AD21,1000000000) -> 1000000000 | Y21: =IF(AND(C21=Rates!$A$46,V21=1),AD21,1000000000) -> 1000000000 | Z21: 2039 | AA21: =Z21*F21 -> 2039 | AB21: =IFERROR(AA21/Calculator!$B$129*Rates!$B$108*Rates!$B$109,0) -> 326.24 | AC21: =IF(Inference!$B$16<=0,1,IF(AB21<=0,1000000000,MAX(1,ROUNDUP(Inference!$B$16/AB21,0)))) -> 1 | AD21: =T21*AC21+AC21/1000000 -> 3.673001
A22: 4 | B22: A100 80 GB - larger models per GPU | C22: Google Cloud | D22: NVIDIA A100 80GB | E22: 80 | F22: 1 | G22: =E22*F22 -> 80 | H22: a2-ultragpu-1g | I22: 12 | J22: 170 | K22: 5.0688 | L22: 2.025 | M22: Published spot rate | N22: =K22*IF(C22=Rates!$A$45,Rates!$B$29,Rates!$C$29) -> 3.54816 | O22: =K22*Rates!$B$30 -> 3700.224 | P22: Single 80 GB GPU on GCP | Q22: Published list price | R22: GCP accelerator-optimized pricing, us-central1 | S22: =C22&" | "&H22 -> Google Cloud | a2-ultragpu-1g | T22: =IF(Calculator!$D$16=Rates!$C$46,L22,IF(Calculator!$D$16=Rates!$C$47,N22,K22)) -> 5.0688 | U22: =IF(OR(Calculator!$B$13=Rates!$A$47,Calculator!$B$13=C22),1,0) -> 1 | V22: =IF(G22>=Calculator!$B$10,1,0) -> 0 | W22: =IF(AND(U22=1,V22=1),AD22,1000000000) -> 1000000000 | X22: =IF(AND(C22=Rates!$A$45,V22=1),AD22,1000000000) -> 1000000000 | Y22: =IF(AND(C22=Rates!$A$46,V22=1),AD22,1000000000) -> 1000000000 | Z22: 2039 | AA22: =Z22*F22 -> 2039 | AB22: =IFERROR(AA22/Calculator!$B$129*Rates!$B$108*Rates!$B$109,0) -> 326.24 | AC22: =IF(Inference!$B$16<=0,1,IF(AB22<=0,1000000000,MAX(1,ROUNDUP(Inference!$B$16/AB22,0)))) -> 1 | AD22: =T22*AC22+AC22/1000000 -> 5.068801
A23: 4 | B23: A100 80 GB - larger models per GPU | C23: Microsoft Azure | D23: NVIDIA A100 80GB | E23: 80 | F23: 2 | G23: =E23*F23 -> 160 | H23: Standard_NC48ads_A100_v4 | I23: 48 | J23: 440 | K23: 7.346 | L23: =K23*IF(C23=Rates!$A$45,Rates!$B$28,Rates!$C$28) -> 1.39574 | M23: Estimated (cloud default factor) | N23: =K23*IF(C23=Rates!$A$45,Rates!$B$29,Rates!$C$29) -> 4.7749 | O23: =K23*Rates!$B$30 -> 5362.58 | P23: Two 80 GB GPUs | Q23: Scaled from the 1-GPU rate | R23: Scaled 2x from NC24ads A100 v4 published rate - confirm in Azure calculator | S23: =C23&" | "&H23 -> Microsoft Azure | Standard_NC48ads_A100_v4 | T23: =IF(Calculator!$D$16=Rates!$C$46,L23,IF(Calculator!$D$16=Rates!$C$47,N23,K23)) -> 7.346 | U23: =IF(OR(Calculator!$B$13=Rates!$A$47,Calculator!$B$13=C23),1,0) -> 1 | V23: =IF(G23>=Calculator!$B$10,1,0) -> 1 | W23: =IF(AND(U23=1,V23=1),AD23,1000000000) -> 7.346001 | X23: =IF(AND(C23=Rates!$A$45,V23=1),AD23,1000000000) -> 1000000000 | Y23: =IF(AND(C23=Rates!$A$46,V23=1),AD23,1000000000) -> 7.346001 | Z23: 2039 | AA23: =Z23*F23 -> 4078 | AB23: =IFERROR(AA23/Calculator!$B$129*Rates!$B$108*Rates!$B$109,0) -> 652.48 | AC23: =IF(Inference!$B$16<=0,1,IF(AB23<=0,1000000000,MAX(1,ROUNDUP(Inference!$B$16/AB23,0)))) -> 1 | AD23: =T23*AC23+AC23/1000000 -> 7.346001
A24: 4 | B24: A100 80 GB - larger models per GPU | C24: Google Cloud | D24: NVIDIA A100 80GB | E24: 80 | F24: 2 | G24: =E24*F24 -> 160 | H24: a2-ultragpu-2g | I24: 24 | J24: 340 | K24: 10.1376 | L24: 4.05 | M24: Published spot rate | N24: =K24*IF(C24=Rates!$A$45,Rates!$B$29,Rates!$C$29) -> 7.09632 | O24: =K24*Rates!$B$30 -> 7400.448 | P24: Two 80 GB GPUs | Q24: Published list price | R24: GCP accelerator-optimized pricing, us-central1 | S24: =C24&" | "&H24 -> Google Cloud | a2-ultragpu-2g | T24: =IF(Calculator!$D$16=Rates!$C$46,L24,IF(Calculator!$D$16=Rates!$C$47,N24,K24)) -> 10.1376 | U24: =IF(OR(Calculator!$B$13=Rates!$A$47,Calculator!$B$13=C24),1,0) -> 1 | V24: =IF(G24>=Calculator!$B$10,1,0) -> 1 | W24: =IF(AND(U24=1,V24=1),AD24,1000000000) -> 10.137601 | X24: =IF(AND(C24=Rates!$A$45,V24=1),AD24,1000000000) -> 10.137601 | Y24: =IF(AND(C24=Rates!$A$46,V24=1),AD24,1000000000) -> 1000000000 | Z24: 2039 | AA24: =Z24*F24 -> 4078 | AB24: =IFERROR(AA24/Calculator!$B$129*Rates!$B$108*Rates!$B$109,0) -> 652.48 | AC24: =IF(Inference!$B$16<=0,1,IF(AB24<=0,1000000000,MAX(1,ROUNDUP(Inference!$B$16/AB24,0)))) -> 1 | AD24: =T24*AC24+AC24/1000000 -> 10.137601
A25: 4 | B25: A100 80 GB - larger models per GPU | C25: Microsoft Azure | D25: NVIDIA A100 80GB | E25: 80 | F25: 4 | G25: =E25*F25 -> 320 | H25: Standard_NC96ads_A100_v4 | I25: 96 | J25: 880 | K25: 14.692 | L25: =K25*IF(C25=Rates!$A$45,Rates!$B$28,Rates!$C$28) -> 2.79148 | M25: Estimated (cloud default factor) | N25: =K25*IF(C25=Rates!$A$45,Rates!$B$29,Rates!$C$29) -> 9.5498 | O25: =K25*Rates!$B$30 -> 10725.16 | P25: Four 80 GB GPUs | Q25: Scaled from the 1-GPU rate | R25: Scaled 4x from NC24ads A100 v4 published rate - confirm in Azure calculator | S25: =C25&" | "&H25 -> Microsoft Azure | Standard_NC96ads_A100_v4 | T25: =IF(Calculator!$D$16=Rates!$C$46,L25,IF(Calculator!$D$16=Rates!$C$47,N25,K25)) -> 14.692 | U25: =IF(OR(Calculator!$B$13=Rates!$A$47,Calculator!$B$13=C25),1,0) -> 1 | V25: =IF(G25>=Calculator!$B$10,1,0) -> 1 | W25: =IF(AND(U25=1,V25=1),AD25,1000000000) -> 14.692001 | X25: =IF(AND(C25=Rates!$A$45,V25=1),AD25,1000000000) -> 1000000000 | Y25: =IF(AND(C25=Rates!$A$46,V25=1),AD25,1000000000) -> 14.692001 | Z25: 2039 | AA25: =Z25*F25 -> 8156 | AB25: =IFERROR(AA25/Calculator!$B$129*Rates!$B$108*Rates!$B$109,0) -> 1304.96 | AC25: =IF(Inference!$B$16<=0,1,IF(AB25<=0,1000000000,MAX(1,ROUNDUP(Inference!$B$16/AB25,0)))) -> 1 | AD25: =T25*AC25+AC25/1000000 -> 14.692001
A26: 4 | B26: A100 80 GB - larger models per GPU | C26: Google Cloud | D26: NVIDIA A100 80GB | E26: 80 | F26: 4 | G26: =E26*F26 -> 320 | H26: a2-ultragpu-4g | I26: 48 | J26: 680 | K26: 20.2752 | L26: 8.1 | M26: Published spot rate | N26: =K26*IF(C26=Rates!$A$45,Rates!$B$29,Rates!$C$29) -> 14.19264 | O26: =K26*Rates!$B$30 -> 14800.896 | P26: Four 80 GB GPUs | Q26: Published list price | R26: GCP accelerator-optimized pricing, us-central1 | S26: =C26&" | "&H26 -> Google Cloud | a2-ultragpu-4g | T26: =IF(Calculator!$D$16=Rates!$C$46,L26,IF(Calculator!$D$16=Rates!$C$47,N26,K26)) -> 20.2752 | U26: =IF(OR(Calculator!$B$13=Rates!$A$47,Calculator!$B$13=C26),1,0) -> 1 | V26: =IF(G26>=Calculator!$B$10,1,0) -> 1 | W26: =IF(AND(U26=1,V26=1),AD26,1000000000) -> 20.275201 | X26: =IF(AND(C26=Rates!$A$45,V26=1),AD26,1000000000) -> 20.275201 | Y26: =IF(AND(C26=Rates!$A$46,V26=1),AD26,1000000000) -> 1000000000 | Z26: 2039 | AA26: =Z26*F26 -> 8156 | AB26: =IFERROR(AA26/Calculator!$B$129*Rates!$B$108*Rates!$B$109,0) -> 1304.96 | AC26: =IF(Inference!$B$16<=0,1,IF(AB26<=0,1000000000,MAX(1,ROUNDUP(Inference!$B$16/AB26,0)))) -> 1 | AD26: =T26*AC26+AC26/1000000 -> 20.275201
A27: 4 | B27: A100 80 GB - larger models per GPU | C27: Google Cloud | D27: NVIDIA A100 80GB | E27: 80 | F27: 8 | G27: =E27*F27 -> 640 | H27: a2-ultragpu-8g | I27: 96 | J27: 1360 | K27: 40.5504 | L27: 16.2 | M27: Published spot rate | N27: =K27*IF(C27=Rates!$A$45,Rates!$B$29,Rates!$C$29) -> 28.38528 | O27: =K27*Rates!$B$30 -> 29601.792 | P27: Eight 80 GB GPUs, 1,360 GB RAM | Q27: Published list price | R27: GCP accelerator-optimized pricing, us-central1 | S27: =C27&" | "&H27 -> Google Cloud | a2-ultragpu-8g | T27: =IF(Calculator!$D$16=Rates!$C$46,L27,IF(Calculator!$D$16=Rates!$C$47,N27,K27)) -> 40.5504 | U27: =IF(OR(Calculator!$B$13=Rates!$A$47,Calculator!$B$13=C27),1,0) -> 1 | V27: =IF(G27>=Calculator!$B$10,1,0) -> 1 | W27: =IF(AND(U27=1,V27=1),AD27,1000000000) -> 40.550401 | X27: =IF(AND(C27=Rates!$A$45,V27=1),AD27,1000000000) -> 40.550401 | Y27: =IF(AND(C27=Rates!$A$46,V27=1),AD27,1000000000) -> 1000000000 | Z27: 2039 | AA27: =Z27*F27 -> 16312 | AB27: =IFERROR(AA27/Calculator!$B$129*Rates!$B$108*Rates!$B$109,0) -> 2609.92 | AC27: =IF(Inference!$B$16<=0,1,IF(AB27<=0,1000000000,MAX(1,ROUNDUP(Inference!$B$16/AB27,0)))) -> 1 | AD27: =T27*AC27+AC27/1000000 -> 40.550401
A28: 5 | B28: H100 NVL 94 GB - single-GPU Hopper | C28: Microsoft Azure | D28: NVIDIA H100 NVL | E28: 94 | F28: 1 | G28: =E28*F28 -> 94 | H28: Standard_NC40ads_H100_v5 | I28: 40 | J28: 320 | K28: 6.98 | L28: =K28*IF(C28=Rates!$A$45,Rates!$B$28,Rates!$C$28) -> 1.3262 | M28: Estimated (cloud default factor) | N28: =K28*IF(C28=Rates!$A$45,Rates!$B$29,Rates!$C$29) -> 4.537 | O28: =K28*Rates!$B$30 -> 5095.4 | P28: Only way to rent ONE H100 on either cloud | Q28: Published list price | R28: Azure East US / East US 2 / West US 2-3 published rate | S28: =C28&" | "&H28 -> Microsoft Azure | Standard_NC40ads_H100_v5 | T28: =IF(Calculator!$D$16=Rates!$C$46,L28,IF(Calculator!$D$16=Rates!$C$47,N28,K28)) -> 6.98 | U28: =IF(OR(Calculator!$B$13=Rates!$A$47,Calculator!$B$13=C28),1,0) -> 1 | V28: =IF(G28>=Calculator!$B$10,1,0) -> 1 | W28: =IF(AND(U28=1,V28=1),AD28,1000000000) -> 6.980001 | X28: =IF(AND(C28=Rates!$A$45,V28=1),AD28,1000000000) -> 1000000000 | Y28: =IF(AND(C28=Rates!$A$46,V28=1),AD28,1000000000) -> 6.980001 | Z28: 3900 | AA28: =Z28*F28 -> 3900 | AB28: =IFERROR(AA28/Calculator!$B$129*Rates!$B$108*Rates!$B$109,0) -> 624 | AC28: =IF(Inference!$B$16<=0,1,IF(AB28<=0,1000000000,MAX(1,ROUNDUP(Inference!$B$16/AB28,0)))) -> 1 | AD28: =T28*AC28+AC28/1000000 -> 6.980001
A29: 5 | B29: H100 NVL 94 GB - single-GPU Hopper | C29: Microsoft Azure | D29: NVIDIA H100 NVL | E29: 94 | F29: 2 | G29: =E29*F29 -> 188 | H29: Standard_NC80adis_H100_v5 | I29: 80 | J29: 640 | K29: 13.96 | L29: =K29*IF(C29=Rates!$A$45,Rates!$B$28,Rates!$C$28) -> 2.6524 | M29: Estimated (cloud default factor) | N29: =K29*IF(C29=Rates!$A$45,Rates!$B$29,Rates!$C$29) -> 9.074 | O29: =K29*Rates!$B$30 -> 10190.8 | P29: Two H100 NVL GPUs | Q29: Scaled from the 1-GPU rate | R29: Scaled 2x from NC40ads H100 v5 published rate - confirm in Azure calculator | S29: =C29&" | "&H29 -> Microsoft Azure | Standard_NC80adis_H100_v5 | T29: =IF(Calculator!$D$16=Rates!$C$46,L29,IF(Calculator!$D$16=Rates!$C$47,N29,K29)) -> 13.96 | U29: =IF(OR(Calculator!$B$13=Rates!$A$47,Calculator!$B$13=C29),1,0) -> 1 | V29: =IF(G29>=Calculator!$B$10,1,0) -> 1 | W29: =IF(AND(U29=1,V29=1),AD29,1000000000) -> 13.960001 | X29: =IF(AND(C29=Rates!$A$45,V29=1),AD29,1000000000) -> 1000000000 | Y29: =IF(AND(C29=Rates!$A$46,V29=1),AD29,1000000000) -> 13.960001 | Z29: 3900 | AA29: =Z29*F29 -> 7800 | AB29: =IFERROR(AA29/Calculator!$B$129*Rates!$B$108*Rates!$B$109,0) -> 1248 | AC29: =IF(Inference!$B$16<=0,1,IF(AB29<=0,1000000000,MAX(1,ROUNDUP(Inference!$B$16/AB29,0)))) -> 1 | AD29: =T29*AC29+AC29/1000000 -> 13.960001
